<?xml version="1.0"?>
<sdf version="1.6">
  <world name="default">

    <include>
      <uri>model://ground_plane</uri>
    </include>

    <include>
      <uri>model://sun</uri>
    </include>

    <scene>
      <shadows>false</shadows>
    </scene>


    <physics type="ode">
      <real_time_update_rate>1000.0</real_time_update_rate>
      <max_step_size>0.001</max_step_size>
      <real_time_factor>1</real_time_factor>
      <ode>
        <solver>
          <type>quick</type>
          <iters>150</iters>
          <precon_iters>0</precon_iters>
          <sor>1.400000</sor>
          <use_dynamic_moi_rescaling>1</use_dynamic_moi_rescaling>
        </solver>
        <constraints>
          <cfm>0.00001</cfm>
          <erp>0.2</erp>
          <contact_max_correcting_vel>2000.000000</contact_max_correcting_vel>
          <contact_surface_layer>0.01000</contact_surface_layer>
        </constraints>
      </ode>
    </physics>

    <model name="rccar_world">
      <static>1</static>
      <include>
        <uri>model://rrcar_world</uri>
      </include>
    </model>

    <model name="rccar"> 
      <pose>-2.0 -0.5 0.01 0.0 0.0 0.0</pose>

      <material name="black">
        <color rgba="0.0 0.0 0.0 1.0"/>
      </material>

      <material name="dark">
        <color rgba="0.3 0.3 0.3 1.0"/>
      </material>

      <material name="light_black">
        <color rgba="0.4 0.4 0.4 1.0"/>
      </material>

      <material name="blue">
        <color rgba="0.0 0.0 0.8 1.0"/>
      </material>

      <material name="green">
        <color rgba="0.0 0.8 0.0 1.0"/>
      </material>

      <material name="grey">
        <color rgba="0.5 0.5 0.5 1.0"/>
      </material>

      <material name="orange">
        <color rgba="1.0 0.4235 0.0392 1.0"/>
      </material>

      <material name="brown">
        <color rgba="0.8706 0.8118 0.7647 1.0"/>
      </material>

      <material name="red">
        <color rgba="0.8 0.0 0.0 1.0"/>
      </material>

      <material name="white">
        <color rgba="1.0 1.0 1.0 1.0"/>
      </material>

      <!-- Define links -->
      <link name="base_footprint"/>

      <joint name="base_joint" type="fixed">
        <parent link="base_footprint"/>
        <child link="base_link"/>
        <origin xyz="0 0 0.010" rpy="0 0 0"/>
      </joint>

      <link name="base_link">
        <visual>
          <origin xyz="-0.064 0 0.0" rpy="0 0 0"/>
          <geometry>
            <mesh filename="package://turtlebot3_description/meshes/bases/waffle_base.stl" scale="0.001 0.001 0.001"/>
          </geometry>
          <material name="light_black"/>
        </visual>

        <collision>
          <origin xyz="-0.064 0 0.047" rpy="0 0 0"/>
          <geometry>
            <box size="0.266 0.266 0.094"/>
          </geometry>
        </collision>

        <inertial>
          <origin xyz="0 0 0" rpy="0 0 0"/>
          <mass value="1.3729096e+00"/>
          <inertia ixx="8.7002718e-03" ixy="-4.7576583e-05" ixz="1.1160499e-04"
                   iyy="1.6421012e-02" iyz="2.1841149e-06"
                   izz="1.8260632e-02"/>
        </inertial>
      </link>

      <joint name="front_left_wheel_joint" type="continuous">
        <parent link="base_link"/>
        <child link="front_left_wheel"/>
        <origin xyz="0.000 0.0825 0.0225" rpy="0 0 0"/>
        <axis xyz="0 1 0"/>
      </joint>

      <link name="front_left_wheel">
        <visual>
          <origin xyz="0.000 0.0825 0.0225" rpy="0 0 0"/>
          <geometry>
            <cylinder radius="0.032" length="0.017"/>
          </geometry>
          <material name="black"/>
        </visual>

        <collision>
          <origin xyz="0.000 0.0825 0.0225" rpy="0 0 0"/>
          <geometry>
            <cylinder radius="0.032" length="0.017"/>
          </geometry>
        </collision>

        <inertial>
          <origin xyz="0 0 0" rpy="0 0 0"/>
          <mass value="1.0000000e-03"/>
          <inertia ixx="4.9999998e-06" ixy="0.0000000e+00" ixz="0.0000000e+00"
                   iyy="2.4999999e-06" iyz="0.0000000e+00"
                   izz="2.4999999e-06"/>
        </inertial>
      </link>

      <!-- Define additional wheels -->

      <!-- Front right wheel -->
      <joint name="front_right_wheel_joint" type="continuous">
        <parent link="base_link"/>
        <child link="front_right_wheel"/>
        <origin xyz="0.000 -0.0825 0.0225" rpy="0 0 0"/>
        <axis xyz="0 1 0"/>
      </joint>

      <link name="front_right_wheel">
        <visual>
          <origin xyz="0.000 -0.0825 0.0225" rpy="0 0 0"/>
          <geometry>
            <cylinder radius="0.032" length="0.017"/>
          </geometry>
          <material name="black"/>
        </visual>

        <collision>
          <origin xyz="0.000 -0.0825 0.0225" rpy="0 0 0"/>
          <geometry>
            <cylinder radius="0.032" length="0.017"/>
          </geometry>
        </collision>

        <inertial>
          <origin xyz="0 0 0" rpy="0 0 0"/>
          <mass value="1.0000000e-03"/>
          <inertia ixx="4.9999998e-06" ixy="0.0000000e+00" ixz="0.0000000e+00"
                   iyy="2.4999999e-06" iyz="0.0000000e+00"
                   izz="2.4999999e-06"/>
        </inertial>
      </link>

      <!-- Rear left wheel -->
      <joint name="rear_left_wheel_joint" type="continuous">
        <parent link="base_link"/>
        <child link="rear_left_wheel"/>
        <origin xyz="0.000 0.0825 -0.0225" rpy="0 0 0"/>
        <axis xyz="0 -1 0"/>
      </joint>

      <link name="rear_left_wheel">
        <visual>
          <origin xyz="0.000 0.0825 -0.0225" rpy="0 0 0"/>
          <geometry>
            <cylinder radius="0.032" length="0.017"/>
          </geometry>
          <material name="black"/>
        </visual>

        <collision>
          <origin xyz="0.000 0.0825 -0.0225" rpy="0 0 0"/>
          <geometry>
            <cylinder radius="0.032" length="0.017"/>
          </geometry>
        </collision>

        <inertial>
          <origin xyz="0 0 0" rpy="0 0 0"/>
          <mass value="1.0000000e-03"/>
          <inertia ixx="4.9999998e-06" ixy="0.0000000e+00" ixz="0.0000000e+00"
                   iyy="2.4999999e-06" iyz="0.0000000e+00"
                   izz="2.4999999e-06"/>
        </inertial>
      </link>

      <!-- Rear right wheel -->
      <joint name="rear_right_wheel_joint" type="continuous">
        <parent link="base_link"/>
        <child link="rear_right_wheel"/>
        <origin xyz="0.000 -0.0825 -0.0225" rpy="0 0 0"/>
        <axis xyz="0 -1 0"/>
      </joint>

      <link name="rear_right_wheel">
        <visual>
          <origin xyz="0.000 -0.0825 -0.0225" rpy="0 0 0"/>
          <geometry>
            <cylinder radius="0.032" length="0.017"/>
          </geometry>
          <material name="black"/>
        </visual>

        <collision>
          <origin xyz="0.000 -0.0825 -0.0225" rpy="0 0 0"/>
          <geometry>
            <cylinder radius="0.032" length="0.017"/>
          </geometry>
        </collision>

        <inertial>
          <origin xyz="0 0 0" rpy="0 0 0"/>
          <mass value="1.0000000e-03"/>
          <inertia ixx="4.9999998e-06" ixy="0.0000000e+00" ixz="0.0000000e+00"
                   iyy="2.4999999e-06" iyz="0.0000000e+00"
                   izz="2.4999999e-06"/>
        </inertial>
      </link>


      


 
      <plugin name="turtlebot3_diff_drive" filename="libgazebo_ros_diff_drive.so">

        <ros>
          <!-- <namespace>/tb3</namespace> -->
        </ros>

        <update_rate>30</update_rate>

        <!-- wheels -->
        <left_joint>wheel_left_joint</left_joint>
        <right_joint>wheel_right_joint</right_joint>

        <!-- kinematics -->
        <wheel_separation>0.287</wheel_separation>
        <wheel_diameter>0.066</wheel_diameter>

        <!-- limits -->
        <max_wheel_torque>20</max_wheel_torque>
        <max_wheel_acceleration>1.0</max_wheel_acceleration>

        <command_topic>cmd_vel</command_topic>

        <!-- output -->
        <publish_odom>true</publish_odom>
        <publish_odom_tf>true</publish_odom_tf>
        <publish_wheel_tf>false</publish_wheel_tf>

        <odometry_topic>odom</odometry_topic>
        <odometry_frame>odom</odometry_frame>
        <robot_base_frame>base_footprint</robot_base_frame>

      </plugin>

      <plugin name="turtlebot3_joint_state" filename="libgazebo_ros_joint_state_publisher.so">
        <ros>
          <!-- <namespace>/tb3</namespace> -->
            <remapping>~/out:=joint_states</remapping>
        </ros>
        <update_rate>30</update_rate>
        <joint_name>wheel_left_joint</joint_name>
        <joint_name>wheel_right_joint</joint_name>
      </plugin>

    </model>

  </world>
</sdf>
